2020-06-18 08:26:42,392 urllib3.connectionpool DEBUG Starting new HTTPS connection (1): api.authy.com:443 : [/var/www/html/electonicswebservice/env/lib/python3.6/site-packages/urllib3/connectionpool.py line 959, in _new_conn ]
2020-06-18 08:26:43,158 urllib3.connectionpool DEBUG https://api.authy.com:443 "GET /protected/json/phones/verification/check?phone_number=9782782776&country_code=%2B91&verification_code=9211 HTTP/1.1" 404 None : [/var/www/html/electonicswebservice/env/lib/python3.6/site-packages/urllib3/connectionpool.py line 437, in _make_request ]
2020-06-18 08:26:43,168 django.request  ERROR Internal Server Error: /api/v1/user/login/otp/verify/ : [/var/www/html/electonicswebservice/env/lib/python3.6/site-packages/django/utils/log.py line 228, in log_response ]
Traceback (most recent call last):
  File "/var/www/html/electonicswebservice/env/lib/python3.6/site-packages/django/core/handlers/exception.py", line 34, in inner
    response = get_response(request)
  File "/var/www/html/electonicswebservice/env/lib/python3.6/site-packages/django/core/handlers/base.py", line 115, in _get_response
    response = self.process_exception_by_middleware(e, request)
  File "/var/www/html/electonicswebservice/env/lib/python3.6/site-packages/django/core/handlers/base.py", line 113, in _get_response
    response = wrapped_callback(request, *callback_args, **callback_kwargs)
  File "/var/www/html/electonicswebservice/env/lib/python3.6/site-packages/django/views/decorators/csrf.py", line 54, in wrapped_view
    return view_func(*args, **kwargs)
  File "/var/www/html/electonicswebservice/env/lib/python3.6/site-packages/django/views/generic/base.py", line 71, in view
    return self.dispatch(request, *args, **kwargs)
  File "/var/www/html/electonicswebservice/env/lib/python3.6/site-packages/rest_framework/views.py", line 505, in dispatch
    response = self.handle_exception(exc)
  File "/var/www/html/electonicswebservice/env/lib/python3.6/site-packages/rest_framework/views.py", line 465, in handle_exception
    self.raise_uncaught_exception(exc)
  File "/var/www/html/electonicswebservice/env/lib/python3.6/site-packages/rest_framework/views.py", line 476, in raise_uncaught_exception
    raise exc
  File "/var/www/html/electonicswebservice/env/lib/python3.6/site-packages/rest_framework/views.py", line 502, in dispatch
    response = handler(request, *args, **kwargs)
  File "/var/www/html/electonicswebservice/env/lib/python3.6/site-packages/rest_framework/decorators.py", line 50, in handler
    return func(*args, **kwargs)
  File "/var/www/html/electonicswebservice/env/lib/python3.6/site-packages/django/utils/decorators.py", line 130, in _wrapped_view
    response = view_func(request, *args, **kwargs)
  File "/var/www/html/electonicswebservice/registration/views.py", line 372, in login_with_otp_verify
    mobile_or_email = form.cleaned_data.get('mobile_or_email')
AttributeError: 'NoneType' object has no attribute 'cleaned_data'
